Workbook

Sheet Instructions
A2: IMPORTANT INSTRUCTIONS
A3: 1 | B3: Ensure all Mandatory fields are completed on the form (Enter N/A if not applicable)
A4: 2 | B4: Once this form is completed, please return in PDF format via Email to your NBCU contact. To save this document as PDF please follow these instructions: 1.Select 'File' in the top left of the form 2.Change file format to 'PDF' 3. Save If you are unable to convert this to PDF, please take a picture of the document with your phone, save it and return it to your NBCU contact. There is also a word format of this document. If required, please get in touch with your NBCU contact.
A5: 3 | B5: The form will be rejected if: (a) It is in an editable version (Word, Excel etc) (b) Some mandatory information is missing
A7: FURTHER INFORMATION ON FORM FIELDS | B7: Field Information
A8: VENDOR INFORMATION The purpose of this section is to collect general vendor information
A9: 1 | B9: ARE YOU A NEW OR EXISTING VENDOR? | C9: If you are a new vendor for NBCU, select 'New.’ If you are an existing vendor requesting a change or adding new bank details, select 'Existing.'
A10: 2 | B10: PAYMENT TYPE | C10: Select the relevant payment type: ACH should be selected for payment made within the USA. Wire / Electronic Bank Transfer can be selected for all other payments
A11: 3 | B11: VENDOR NAME | C11: Enter Company Name or if individual, please provide your full name
A12: 4 | B12: VENDOR ADDRESS | C12: Enter the Company or Trading Address
A13: 5 | B13: TAX ID / SSN / VAT ID / TAX NUMBER | C13: Enter the relevant tax information as applicable
A14: 6 | B14: REMITTANCE ADVICE EMAIL | C14: This email address will be used to contact you when NBCU issues a payment. This email address may also be used to validate change requests received.
A15: NEW BANK DETAILS This section requires information on the new bank account to be set up in our system.
A16: 7 | B16: BANK ACCOUNT HOLDER / PAYEE NAME | C16: Enter the bank account holder name of the new account
A17: 8 | B17: BANK NAME | C17: Enter bank name of the new account
A18: 9 | B18: BANK BRANCH ADDRESS | C18: Enter the bank branch address of the new account
A19: 10 | B19: BANK ACCOUNT NUMBER | C19: Enter the new bank account number
A20: 11 | B20: SELECT BANK COUNTRY | C20: Select the country of the new bank account
A21: 12 | B21: BANK ACCOUNT CURRENCY | C21: Please enter the 3-digit currency code (i.e. USD, EUR). If you are unsure of the currency code refer to: https://www.iban.com/currency-codes
A22: COUNTRY SPECIFIC BANK DETAILS This section will show the banking information we require based on the new bank account country
A23: 13 | B23: ABA ACH ROUTING - 9 DIGITS | C23: Enter the bank ABA routing number - 9 digit routing number required for ACH payment.
A24: 14 | B24: ABA WIRE ROUTING - 9 DIGITS | C24: Enter the bank ABA routing number - 9 digit routing number required for WIRE payment. Some financial institutions use the same ABA for Wires & ACH. If in doubt, please contact your financial institution for clarification.
A25: 15 | B25: SWIFT / BIC - 8 OR 11 DIGITS | C25: Enter a valid SWIFT / BIC number, this is used to identify banks and financial institutions globally, they consists of 8-11 characters.
A26: 16 | B26: IBAN - NO OF DIGITS VARIES BY COUNTRY | C26: Enter a valid IBAN, this is a standard international numbering system developed to identify a bank account. If in doubt, contact your bank or use this link https://www.iban.com/calculate-iban
A27: 17 | B27: SORT CODE - 6 DIGITS | C27: Enter a valid 6 digit bank sort code, this is used in the UK bank account information to identify both the bank and the branch where the account is held.
A28: 18 | B28: BSB - 6 DIGITS | C28: Enter a valid 6 digit BSB code, this is used in Australia to identify the bank branch & financial institutions.
A29: 19 | B29: BANK BRANCH OR TRANSIT CODE - 5 DIGITS BANK INSTITUTION NUMBER - 3 DIGITS | C29: Enter a valid 5 digit bank branch or transit code, this is used in Canada to identify the bank branch. Enter a valid 3 digit bank institution number, this is used to identify a certain bank.
A30: 20 | B30: IFSC NUMBER - 11 DIGITS | C30: Enter a valid 11 digit IFSC number, this is used in India to identify the bank branch participating in any RBI regulated funds transfer system.
A31: 21 | B31: BANK BRANCH NAME | C31: Enter the bank branch name
A32: 22 | B32: CLABE NUMBER - 18 DIGITS | C32: Enter a valid 18 digit CLABE number (Clave Bancaria Estandarizada), this is used in Mexico to send and receive international transfers. It guarantees that inter-bank fund transfers and automatic service charges are made to the correct accounts.
A33: 23 | B33: BANKGIRO NUMBER - 7 OR 8 DIGITS | C33: Enter a valid 7 - 8 digit Bankgiro number, this is used in Sweden as a proprietary clearing system (a giro) for banks based in Sweden only. This cannot be used when paying from other countries or in other currencies than SEK.
A34: 24 | B34: ISR (ESR) NUMBER, POSTBANK ACCOUNT, BANK NUMBER | C34: Enter a valid 27 digit code, this is used in Switzerland as a payment procedure offered by the Swiss Postal Service to firms based in Switzerland. Postbank account and Bank Number can also be given here.
A35: 25 | B35: OTHER BANK INFORMATION NOT LISTED ABOVE | C35: Enter any information needed which has not been included in the above fields, but will be required for NBCU to make payment to you.
A36: INTERMEDIARY BANK DETAIL (IF APPLICABLE) This section should be completed if you require NBCU to pay you through an Intermediary bank account. Failure to provide Intermediary/Correspondent Bank information when required may result in additional fees deducted from the payment and/or delayed/returned payments. NBCUniversal is not responsible for fees or delays in these cases.
A37: 26 | B37: INTERMEDIARY BANK REQUIRED? | C37: Select 'No' if there is no Intermediary bank required. If NBCU is required to pay through an Intermediary Bank please select 'Yes'. Field 27 to 30 will be mandatory if 'Yes' is selected
A38: 27 | B38: INTERMEDIARY BANK NAME | C38: Enter the new Intermediary Bank Name
A39: 28 | B39: INTERMEDIARY BANK COUNTRY | C39: Select the new Intermediary Bank Country
A40: 29 | B40: INTERMEDIARY SWIFT CODE | C40: Enter the swift code of the new Intermediary Bank
A41: 30 | B41: INTERMEDIARY BANK KEY/ BSB / SORT CODE / ABA ROUTING | C41: Enter the relevant banking information for the new Intermediary Bank
A42: PREVIOUS BANK DETAILS This section will be mandatory if you are an existing vendor. Please enter the information of the previous bank account we hold on our records.
...

Sheet Form 
B2: NBCU Global Vendor Bank Detail Form
B3: VENDOR INFORMATION
B4: ARE YOU A NEW OR EXISTING VENDOR? | C4: SELECT | G4: Mandatory
B5: PAYMENT TYPE | C5: SELECT | G5: Mandatory
B6: VENDOR NAME | G6: =IF((OR(C4="NEW ",C4="EXISTING ")),"Mandatory","N/A") -> N/A
B7: VENDOR ADDRESS | G7: =IF((OR(C4="NEW ",C4="EXISTING ")),"Mandatory","N/A") -> N/A
B8: TAX ID / SSN / VAT ID / TAX NUMBER | G8: =IF((OR(C4="NEW ",C4="EXISTING ")),"Mandatory","N/A") -> N/A
B9: REMITTANCE ADVICE EMAIL | G9: =IF((OR(C4="NEW ",C4="EXISTING ")),"Mandatory","N/A") -> N/A
B10: NEW BANK DETAILS
B11: BANK ACCOUNT HOLDER / PAYEE NAME | G11: =IF((OR(C4="NEW ",C4="EXISTING ")),"Mandatory","N/A") -> N/A
B12: BANK NAME | G12: =IF((OR(C4="NEW ",C4="EXISTING ")),"Mandatory","N/A") -> N/A
B13: BANK BRANCH ADDRESS | G13: =IF((OR(C4="NEW ",C4="EXISTING ")),"Mandatory","N/A") -> N/A
B14: BANK ACCOUNT NUMBER | G14: =IF((OR(C4="NEW ",C4="EXISTING ")),"Mandatory","N/A") -> N/A
B15: SELECT BANK COUNTRY | C15: SELECT | G15: =IF((OR(C4="NEW ",C4="EXISTING ")),"Mandatory","N/A") -> N/A
B16: BANK ACCOUNT CURRENCY | G16: =IF((OR(C4="NEW ",C4="EXISTING ")),"Mandatory","N/A") -> N/A
B17: COUNTRY SPECIFIC BANK INFORMATION
B18: ABA ACH ROUTING - 9 DIGITS | C18: US ONLY | G18: =IF((AND(C5="ACH",C15="USA")),"Mandatory","N/A") -> N/A
B19: ABA WIRE ROUTING - 9 DIGITS | C19: US ONLY | G19: =IF((AND(C5="WIRE / ELECTRONIC BANK TRANSFER",C15="USA")),"Mandatory","N/A") -> N/A
B20: SWIFT / BIC - 8 OR 11 DIGITS | C20: ALL COUNTRIES | G20: =IF(C5="WIRE / ELECTRONIC BANK TRANSFER","Mandatory","N/A") -> N/A
B21: IBAN - NO OF DIGITS VARIES BY COUNTRY | C21: EU & OTHER COUNTRIES | G21: =VLOOKUP(C$15,'Drop Down 1'!A:K,2,0) -> N/A
B22: SORT CODE - 6 DIGITS | C22: UK ONLY | G22: =VLOOKUP(C$15,'Drop Down 1'!A:K,3,0) -> N/A
B23: BSB - 6 DIGITS | C23: AUSTRALIA & NEW ZEALAND ONLY | G23: =VLOOKUP(C$15,'Drop Down 1'!A:K,4,0) -> N/A
B24: BANK BRANCH OR TRANSIT CODE - 5 DIGITS BANK INSTITUTION NUMBER - 3 DIGITS | C24: CANADA ONLY | G24: =VLOOKUP(C$15,'Drop Down 1'!A:K,5,0) -> N/A
B25: IFSC NUMBER - 11 DIGITS | C25: INDIA ONLY | G25: =VLOOKUP(C$15,'Drop Down 1'!A:K,6,0) -> N/A
B26: BANK BRANCH NAME | C26: JAPAN ONLY | G26: =VLOOKUP(C$15,'Drop Down 1'!A:K,7,0) -> N/A
B27: CLABE NUMBER - 18 DIGITS | C27: MEXICO ONLY | G27: =VLOOKUP(C$15,'Drop Down 1'!A:K,8,0) -> N/A
B28: BANKGIRO NUMBER - 7 OR 8 DIGITS | C28: SWEDEN ONLY | G28: =VLOOKUP(C$15,'Drop Down 1'!A:K,9,0) -> N/A
B29: ISR (ESR) NUMBER, POSTBANK ACCOUNT, BANK NUMBER | C29: SWITZERLAND ONLY | G29: =VLOOKUP(C$15,'Drop Down 1'!A:K,10,0) -> N/A
B30: OTHER BANK INFORMATION NOT LISTED ABOVE | G30: =VLOOKUP(C$15,'Drop Down 1'!A:K,11,0) -> N/A
B31: INTERMEDIARY BANK DETAIL (IF APPLICABLE)
B32: INTERMEDIARY BANK REQUIRED? | C32: SELECT | G32: Select from drop down
B33: INTERMEDIARY BANK NAME | G33: =IF(C32="YES ","Mandatory","N/A") -> N/A
B34: INTERMEDIARY BANK COUNTRY | C34: SELECT | G34: =IF(C32="YES ","Mandatory","N/A") -> N/A
B35: INTERMEDIARY SWIFT CODE | G35: =IF(C32="YES ","Mandatory","N/A") -> N/A
B36: INTERMEDIARY BANK KEY/ BSB / SORT CODE / ABA ROUTING | G36: =IF(C32="YES ","Mandatory","N/A") -> N/A
B37: PREVIOUS BANK DETAILS
B38: BANK ACCOUNT HOLDER / PAYEE NAME | G38: =IF(C4="EXISTING ","Mandatory","N/A") -> N/A
B39: BANK NAME | G39: =IF(C4="EXISTING ","Mandatory","N/A") -> N/A
B40: BANK ACCOUNT NUMBER | G40: =IF(C4="EXISTING ","Mandatory","N/A") -> N/A
B41: IS THIS BANK ACCOUNT CLOSED? | C41: SELECT | G41: =IF(C4="EXISTING ","Mandatory","N/A") -> N/A
...

Sheet Drop Down 1
A1: 1 | B1: 2 | C1: 3 | D1: 4 | E1: 5 | F1: 6 | G1: 7 | H1: 8 | I1: 9 | J1: 10 | K1: 11
A2: Bank Ctry | B2: IBAN - NO OF DIGITS VARIES BY COUNTRY | C2: SORT CODE - 6 DIGITS | D2: BSB - 6 DIGITS | E2: TRANSIT CODE - 5 DIGITS | F2: IFSC NUMBER - 11 DIGITS | G2: BANK BRANCH NAME | H2: CLABE NUMBER - 18 DIGITS | I2: BANKGIRO NUMBER - 7 OR 8 DIGITS | J2: ISR (ESR) NUMBER, POSTBANK ACCOUNT, BANK NUMBER | K2: OTHER BANK INFORMATION NOT LISTED ABOVE
A3: SELECT | B3: N/A | C3: N/A | D3: N/A | E3: N/A | F3: N/A | G3: N/A | H3: N/A | I3: N/A | J3: N/A | K3: N/A
A4: OTHER -Add country in comments | B4: Optional | C4: Optional | D4: Optional | E4: Optional | F4: Optional | G4: Optional | H4: Optional | I4: Optional | J4: Optional | K4: Optional
A5: ALBANIA | B5: Optional | C5: N/A | D5: N/A | E5: N/A | F5: N/A | G5: N/A | H5: N/A | I5: N/A | J5: N/A | K5: Optional
A6: ARGENTINA | B6: Optional | C6: N/A | D6: N/A | E6: N/A | F6: N/A | G6: N/A | H6: N/A | I6: N/A | J6: N/A | K6: Optional
A7: AUSTRALIA | B7: Optional | C7: N/A | D7: Mandatory | E7: N/A | F7: N/A | G7: N/A | H7: N/A | I7: N/A | J7: N/A | K7: Optional
A8: AUSTRIA | B8: Mandatory | C8: N/A | D8: N/A | E8: N/A | F8: N/A | G8: N/A | H8: N/A | I8: N/A | J8: N/A | K8: Optional
A9: BAHAMAS | B9: Optional | C9: N/A | D9: N/A | E9: N/A | F9: N/A | G9: N/A | H9: N/A | I9: N/A | J9: N/A | K9: Optional
A10: BAHRAIN | B10: Mandatory | C10: N/A | D10: N/A | E10: N/A | F10: N/A | G10: N/A | H10: N/A | I10: N/A | J10: N/A | K10: Optional
A11: BARBADOS | B11: Optional | C11: N/A | D11: N/A | E11: N/A | F11: N/A | G11: N/A | H11: N/A | I11: N/A | J11: N/A | K11: Optional
A12: BELARUS | B12: Mandatory | C12: N/A | D12: N/A | E12: N/A | F12: N/A | G12: N/A | H12: N/A | I12: N/A | J12: N/A | K12: Optional
A13: BELGIUM | B13: Mandatory | C13: N/A | D13: N/A | E13: N/A | F13: N/A | G13: N/A | H13: N/A | I13: N/A | J13: N/A | K13: Optional
... A133: VIETNAM | B133: Optional | C133: N/A | D133: N/A | E133: N/A | F133: N/A | G133: N/A | H133: N/A | I133: N/A | J133: N/A | K133: Optional

Sheet Drop Down 2
A1: NEW / EXISTING VENDOR | B1: TYPE OF PAYMENT | C1: INTERMEDIARY BANK? | D1: INTERMEDIARY BANK COUNTRY | E1: IS THIS BANK ACCOUNT CLOSED?
A2: SELECT | B2: SELECT | C2: SELECT | D2: SELECT | E2: SELECT
A3: NEW | B3: ACH | C3: YES | D3: ALBANIA | E3: YES
A4: EXISTING | B4: WIRE / ELECTRONIC BANK TRANSFER | C4: NO | D4: ARGENTINA | E4: NO
D5: AUSTRALIA
D6: AUSTRIA
D7: BAHAMAS
D8: BARBADOS
D9: BELARUS
D10: BELGIUM
D11: BRAZIL
D12: BULGARIA
D13: CANADA
D14: CAYMAN ISLANDS
D15: CHINA
D16: COLOMBIA
... D79: VENEZUELA
